<?xml version="1.0"?>
<robot name= "eddie">
	
    <material name="gray">
        <color rgba="0.5 0.5 0.5 1"/>
    </material>
        
    <material name="blue">
        <color rgba="0 0 0.5 1" />
    </material>
    
<!-- base_footprint (projection of base_link on the ground) -->

    <link name="base_footprint"/>
    
    <joint name="base_joint" type="fixed">
        <parent link="base_footprint"/>
        <child link="base_link"/>
        <origin xyz="0 0 0.13385" rpy="0 0 0"/>
    </joint>
    
<!-- base_link -->
    
    <link name="base_link">
    	<visual>
    	    <geometry>
    	        <cylinder radius="0.2255" length="0.2217"/>
    	    </geometry>
    	    <origin xyz="0 0 0" rpy ="0 0 0"/>
    	    <material name ="blue"/>
    	</visual>
    </link>
    
<!--base_link to base_scan -->
    
    <joint name= "base_scan_joint" type= "fixed">
    	<parent link= "base_link"/>
    	<child link= "base_scan"/>
    	<origin xyz= "0 0 0.13835" rpy="0 0 0"/>
    </joint>
    
    <link name="base_scan">
    	<visual>
    		<geometry>
    			<cylinder radius="0.07" length= "0.055"/>
    		</geometry>
    		<oringin xyz= "0 0 0" rpy= "0 0 0 "/>
    		<material name="gray"/>
    	</visual>
    </link>
<!-- imu link -->

    <joint name= "imu_link" type="fixed">
        <parent link="base_link"/>
        <child link="imu_link"/>
        <oringin xyz ="0 0 0 " rpy ="0 0 0"/>
    </joint>
    
    <link name = "imu_link">
        <visual>
            <geometry>
                <box size="0.0256 0.0176 0.0015"/>
            </geometry>
            <material name = "gray"/>
        </visual>
    </link>
    
<!-- Wheels (2 differential wheels + 2 caster wheel to keep the balance) -->
    
    <joint name="base_left_wheel_joint" type="continuous">
        <parent link="base_link"/>
        <child link="left_wheel"/>
        <origin xyz="0 0.195 -0.06215" rpy="0 0 0"/>
        <axis xyz="0 1 0"/>
    </joint>

    <link name="left_wheel">
        <visual>
            <geometry>
                <cylinder radius="0.0765" length="0.03175"/>
            </geometry>
            <origin xyz="0 0 0" rpy="1.57 0 0" />
            <material name="gray" />
        </visual>
    </link>
    
    <joint name="base_right_wheel_joint" type="continuous">
        <parent link="base_link"/>
        <child link="right_wheel"/>
        <origin xyz="0 -0.195 -0.06215" rpy="0 0 0"/>
        <axis xyz="0 1 0"/>
    </joint>

    <link name="right_wheel">
        <visual>
            <geometry>
                <cylinder radius="0.0765" length="0.03175"/>
            </geometry>
            <origin xyz="0 0 0" rpy="1.57 0 0" />
            <material name="gray" />
        </visual>
    </link>
    
    <joint name="base_front_caster" type="fixed">
        <parent link="base_link"/>
        <child link="front_caster"/>
        <origin xyz = "0.1764 0 -0.08475 " rpy = "0 0 0"/>
        <material name = "gray"/>
    </joint>

    <link name="front_caster">
        <visual>
            <geometry>
                <sphere radius="0.0491" />
            </geometry>
            <origin xyz="0 0 0" rpy="0 0 0" />
            <material name="gray" />
        </visual>
    </link>
    
        
    <joint name="base_back_caster" type="fixed">
        <parent link="base_link"/>
        <child link="back_caster"/>
        <origin xyz = "-0.1764 0 -0.08475 " rpy = "0 0 0"/>
        <material name = "gray"/>
    </joint>

    <link name="back_caster">
        <visual>
            <geometry>
                <sphere radius="0.0491" />
            </geometry>
            <origin xyz="0 0 0" rpy="0 0 0" />
            <material name="gray" />
        </visual>
    </link>
</robot>    
